<mujoco model="freight_panda">
    
    <body name="chassis" pos="0 0 0" euler='0 0 0'>
        <joint type="free"/>

        <geom type="mesh" contype="0" conaffinity="0" group="1" density="0" rgba="0.356 0.361 0.376 1" mesh="base_link"/>
        <geom type="mesh" contype="1" conaffinity="1" rgba="0.356 0.361 0.376 1" friction="0.3 0.1 0.1" mesh="base_link_collision" priority="1"/>

        <geom pos="-0.12465 0.23892 0.31127" quat="0.707105 0.707108 0 0" type="mesh" contype="0" conaffinity="0" group="1" density="0" rgba="0.8 0 0 1" mesh="estop_link"/>
        <geom pos="-0.12465 0.23892 0.31127" quat="0.707105 0.707108 0 0" type="mesh" rgba="0.8 0 0 1" mesh="estop_link_collision"/>

        <geom pos="0.235 0 0.2878" quat="0 1 0 0" type="mesh" contype="0" conaffinity="0" group="1" density="0" rgba="0.792157 0.819608 0.933333 1" mesh="laser_link"/>
        <geom pos="0.235 0 0.2878" quat="0 1 0 0" type="mesh" rgba="0.792157 0.819608 0.933333 1" mesh="laser_link_collision"/>

        <body name="r_wheel_link" pos="0.0012914 -0.18738 0.055325" euler='1.5708 0 0'>
            <inertial pos="0 0 0" mass="4.3542" diaginertia="0.005 0.0045 0.0045"/>
            <joint name="r_wheel_joint" pos="0 0 0" axis="0 0 -1" type="hinge" damping="0.1"/>
            <geom size="0.058 0.058 0.05" type="ellipsoid" contype="1" conaffinity="1" />
        </body>
        <body name="l_wheel_link" pos="0.0012914 0.18738 0.055325" euler='1.5708 0 0'>
            <inertial pos="0 0 0" mass="4.3542" diaginertia="0.005 0.0045 0.0045"/>
            <joint name="l_wheel_joint" pos="0 0 0" axis="0 0 -1" type="hinge" damping="0.1"/>
            <geom size="0.058 0.058 0.05" type="ellipsoid" contype="1" conaffinity="1" />
        </body>
        <body name="link0" childclass="panda" pos="0 0 0.36">
            <include file="panda.xml"/>
        </body>
    </body>

</mujoco>
