<mujoco model="freight">
    <geom type="mesh" mesh="base_link" rgba="0.656 0.661 0.676 1" class="freight_visual"/>
    <geom type="mesh" contype="1" conaffinity="1" friction="0.3 0.1 0.1" mesh="base_link_collision" priority="1" class="freight_collision"/>

    <!-- -0.12465 0.23892 0.31127 -->
    <geom pos="-0.1488 0.287 0.3735" quat="0.707105 0.707108 0 0" type="mesh" mesh="estop_link" rgba="0.8 0 0 1" class="freight_visual"/>
    <geom pos="-0.1488 0.287 0.3735" quat="0.707105 0.707108 0 0" type="mesh" mesh="estop_link_collision" class="freight_collision"/>

    <geom pos="0.282 0 0.39536" quat="0 1 0 0" type="mesh" mesh="laser_link" class="freight_visual"/>
    <geom pos="0.282 0 0.39536" quat="0 1 0 0" type="mesh" mesh="laser_link_collision" class="freight_collision"/>

    <body name="r_wheel_link" pos="0.00154968 -0.224856 0.06639" euler='1.5708 0 0'>
        <inertial pos="0 0 0" mass="4.3542" diaginertia="0.005 0.0045 0.0045"/>
        <joint name="r_wheel_joint" pos="0 0 0" axis="0 0 -1" type="hinge" damping="0.1"/>
        <geom size="0.07 0.07 0.05" type="ellipsoid" contype="1" conaffinity="1" class="freight_collision"/>
        <geom size="0.07 0.07 0.05" type="ellipsoid" class="freight_visual"/>
    </body>
    <body name="l_wheel_link" pos="0.00154968 0.224856 0.06639" euler='1.5708 0 0'>
        <inertial pos="0 0 0" mass="4.3542" diaginertia="0.005 0.0045 0.0045"/>
        <joint name="l_wheel_joint" pos="0 0 0" axis="0 0 -1" type="hinge" damping="0.1"/>
        <geom size="0.07 0.07 0.05" type="ellipsoid" contype="1" conaffinity="1" class="freight_collision"/>
        <geom size="0.07 0.07 0.05" type="ellipsoid" class="freight_visual"/>
    </body>
</mujoco>